2020-02-14 09:23:07,633 ERROR: Exception on / [GET] [in /Volumes/Work/Flask_test/Flask_Mega_Tutorial/envf/lib/python3.6/site-packages/flask/app.py:1891]
Traceback (most recent call last):
  File "/Volumes/Work/Flask_test/Flask_Mega_Tutorial/envf/lib/python3.6/site-packages/flask/app.py", line 2446, in wsgi_app
    response = self.full_dispatch_request()
  File "/Volumes/Work/Flask_test/Flask_Mega_Tutorial/envf/lib/python3.6/site-packages/flask/app.py", line 1951, in full_dispatch_request
    rv = self.handle_user_exception(e)
  File "/Volumes/Work/Flask_test/Flask_Mega_Tutorial/envf/lib/python3.6/site-packages/flask/app.py", line 1820, in handle_user_exception
    reraise(exc_type, exc_value, tb)
  File "/Volumes/Work/Flask_test/Flask_Mega_Tutorial/envf/lib/python3.6/site-packages/flask/_compat.py", line 39, in reraise
    raise value
  File "/Volumes/Work/Flask_test/Flask_Mega_Tutorial/envf/lib/python3.6/site-packages/flask/app.py", line 1949, in full_dispatch_request
    rv = self.dispatch_request()
  File "/Volumes/Work/Flask_test/Flask_Mega_Tutorial/envf/lib/python3.6/site-packages/flask/app.py", line 1935, in dispatch_request
    return self.view_functions[rule.endpoint](**req.view_args)
  File "/Volumes/Work/Flask_test/Flask_Mega_Tutorial/envf/lib/python3.6/site-packages/flask_login/utils.py", line 261, in decorated_view
    return func(*args, **kwargs)
  File "/Volumes/Work/Flask_test/Flask_Mega_Tutorial/Flask_mega/app/main/routes.py", line 47, in index
    prev_url=prev_url)
  File "/Volumes/Work/Flask_test/Flask_Mega_Tutorial/envf/lib/python3.6/site-packages/flask/templating.py", line 140, in render_template
    ctx.app,
  File "/Volumes/Work/Flask_test/Flask_Mega_Tutorial/envf/lib/python3.6/site-packages/flask/templating.py", line 120, in _render
    rv = template.render(context)
  File "/Volumes/Work/Flask_test/Flask_Mega_Tutorial/envf/lib/python3.6/site-packages/jinja2/asyncsupport.py", line 76, in render
    return original_render(self, *args, **kwargs)
  File "/Volumes/Work/Flask_test/Flask_Mega_Tutorial/envf/lib/python3.6/site-packages/jinja2/environment.py", line 1008, in render
    return self.environment.handle_exception(exc_info, True)
  File "/Volumes/Work/Flask_test/Flask_Mega_Tutorial/envf/lib/python3.6/site-packages/jinja2/environment.py", line 780, in handle_exception
    reraise(exc_type, exc_value, tb)
  File "/Volumes/Work/Flask_test/Flask_Mega_Tutorial/envf/lib/python3.6/site-packages/jinja2/_compat.py", line 37, in reraise
    raise value.with_traceback(tb)
  File "/Volumes/Work/Flask_test/Flask_Mega_Tutorial/Flask_mega/app/templates/index.html", line 2, in top-level template code
    {% import 'bootstrap/wtf.html' as wtf %}
  File "/Volumes/Work/Flask_test/Flask_Mega_Tutorial/Flask_mega/app/templates/base.html", line 1, in top-level template code
    {% extends 'bootstrap/base.html' %}
  File "/Volumes/Work/Flask_test/Flask_Mega_Tutorial/envf/lib/python3.6/site-packages/flask_bootstrap/templates/bootstrap/base.html", line 1, in top-level template code
    {% block doc -%}
  File "/Volumes/Work/Flask_test/Flask_Mega_Tutorial/envf/lib/python3.6/site-packages/flask_bootstrap/templates/bootstrap/base.html", line 4, in block "doc"
    {%- block html %}
  File "/Volumes/Work/Flask_test/Flask_Mega_Tutorial/envf/lib/python3.6/site-packages/flask_bootstrap/templates/bootstrap/base.html", line 20, in block "html"
    {% block body -%}
  File "/Volumes/Work/Flask_test/Flask_Mega_Tutorial/envf/lib/python3.6/site-packages/flask_bootstrap/templates/bootstrap/base.html", line 21, in block "body"
    {% block navbar %}
  File "/Volumes/Work/Flask_test/Flask_Mega_Tutorial/Flask_mega/app/templates/base.html", line 25, in block "navbar"
    <form class="navbar-form navbar-left" method="get" action="{{ url_for('main.saerch') }}">
  File "/Volumes/Work/Flask_test/Flask_Mega_Tutorial/envf/lib/python3.6/site-packages/flask/helpers.py", line 370, in url_for
    return appctx.app.handle_url_build_error(error, endpoint, values)
  File "/Volumes/Work/Flask_test/Flask_Mega_Tutorial/envf/lib/python3.6/site-packages/flask/app.py", line 2215, in handle_url_build_error
    reraise(exc_type, exc_value, tb)
  File "/Volumes/Work/Flask_test/Flask_Mega_Tutorial/envf/lib/python3.6/site-packages/flask/_compat.py", line 39, in reraise
    raise value
  File "/Volumes/Work/Flask_test/Flask_Mega_Tutorial/envf/lib/python3.6/site-packages/flask/helpers.py", line 358, in url_for
    endpoint, values, method=method, force_external=external
  File "/Volumes/Work/Flask_test/Flask_Mega_Tutorial/envf/lib/python3.6/site-packages/werkzeug/routing.py", line 2020, in build
    raise BuildError(endpoint, values, method, self)
werkzeug.routing.BuildError: Could not build url for endpoint 'main.saerch'. Did you mean 'main.search' instead?
2020-02-14 09:40:01,957 INFO: Microblog startup [in /Volumes/Work/Flask_test/Flask_Mega_Tutorial/Flask_mega/app/__init__.py:79]
2020-02-14 09:40:13,077 ERROR: Exception on /search [GET] [in /Volumes/Work/Flask_test/Flask_Mega_Tutorial/envf/lib/python3.6/site-packages/flask/app.py:1891]
Traceback (most recent call last):
  File "/Volumes/Work/Flask_test/Flask_Mega_Tutorial/envf/lib/python3.6/site-packages/flask/app.py", line 2446, in wsgi_app
    response = self.full_dispatch_request()
  File "/Volumes/Work/Flask_test/Flask_Mega_Tutorial/envf/lib/python3.6/site-packages/flask/app.py", line 1951, in full_dispatch_request
    rv = self.handle_user_exception(e)
  File "/Volumes/Work/Flask_test/Flask_Mega_Tutorial/envf/lib/python3.6/site-packages/flask/app.py", line 1820, in handle_user_exception
    reraise(exc_type, exc_value, tb)
  File "/Volumes/Work/Flask_test/Flask_Mega_Tutorial/envf/lib/python3.6/site-packages/flask/_compat.py", line 39, in reraise
    raise value
  File "/Volumes/Work/Flask_test/Flask_Mega_Tutorial/envf/lib/python3.6/site-packages/flask/app.py", line 1949, in full_dispatch_request
    rv = self.dispatch_request()
  File "/Volumes/Work/Flask_test/Flask_Mega_Tutorial/envf/lib/python3.6/site-packages/flask/app.py", line 1935, in dispatch_request
    return self.view_functions[rule.endpoint](**req.view_args)
  File "/Volumes/Work/Flask_test/Flask_Mega_Tutorial/envf/lib/python3.6/site-packages/flask_login/utils.py", line 261, in decorated_view
    return func(*args, **kwargs)
  File "/Volumes/Work/Flask_test/Flask_Mega_Tutorial/Flask_mega/app/main/routes.py", line 147, in search
    posts, total = Post.search(g.search_form.q.data, page, current_app.config['POSTS_PER_PAGE'])
AttributeError: type object 'Post' has no attribute 'search'
2020-02-14 09:43:24,394 INFO: Microblog startup [in /Volumes/Work/Flask_test/Flask_Mega_Tutorial/Flask_mega/app/__init__.py:79]
2020-02-14 09:43:32,719 ERROR: Exception on /search [GET] [in /Volumes/Work/Flask_test/Flask_Mega_Tutorial/envf/lib/python3.6/site-packages/flask/app.py:1891]
Traceback (most recent call last):
  File "/Volumes/Work/Flask_test/Flask_Mega_Tutorial/envf/lib/python3.6/site-packages/flask/app.py", line 2446, in wsgi_app
    response = self.full_dispatch_request()
  File "/Volumes/Work/Flask_test/Flask_Mega_Tutorial/envf/lib/python3.6/site-packages/flask/app.py", line 1951, in full_dispatch_request
    rv = self.handle_user_exception(e)
  File "/Volumes/Work/Flask_test/Flask_Mega_Tutorial/envf/lib/python3.6/site-packages/flask/app.py", line 1820, in handle_user_exception
    reraise(exc_type, exc_value, tb)
  File "/Volumes/Work/Flask_test/Flask_Mega_Tutorial/envf/lib/python3.6/site-packages/flask/_compat.py", line 39, in reraise
    raise value
  File "/Volumes/Work/Flask_test/Flask_Mega_Tutorial/envf/lib/python3.6/site-packages/flask/app.py", line 1949, in full_dispatch_request
    rv = self.dispatch_request()
  File "/Volumes/Work/Flask_test/Flask_Mega_Tutorial/envf/lib/python3.6/site-packages/flask/app.py", line 1935, in dispatch_request
    return self.view_functions[rule.endpoint](**req.view_args)
  File "/Volumes/Work/Flask_test/Flask_Mega_Tutorial/envf/lib/python3.6/site-packages/flask_login/utils.py", line 261, in decorated_view
    return func(*args, **kwargs)
  File "/Volumes/Work/Flask_test/Flask_Mega_Tutorial/Flask_mega/app/main/routes.py", line 147, in search
    posts, total = Post.search(g.search_form.q.data, page, current_app.config['POSTS_PER_PAGE'])
  File "/Volumes/Work/Flask_test/Flask_Mega_Tutorial/Flask_mega/app/models.py", line 89, in search
    ids, total = query_index(cls.__tablename__, expression, page, per_page)
  File "/Volumes/Work/Flask_test/Flask_Mega_Tutorial/Flask_mega/app/search.py", line 22, in query_index
    'from': (page - 1) * per_page, 'size': per_page}
  File "/Volumes/Work/Flask_test/Flask_Mega_Tutorial/envf/lib/python3.6/site-packages/elasticsearch/client/utils.py", line 84, in _wrapped
    return func(*args, params=params, **kwargs)
  File "/Volumes/Work/Flask_test/Flask_Mega_Tutorial/envf/lib/python3.6/site-packages/elasticsearch/client/__init__.py", line 1548, in search
    "GET", _make_path(index, doc_type, "_search"), params=params, body=body
  File "/Volumes/Work/Flask_test/Flask_Mega_Tutorial/envf/lib/python3.6/site-packages/elasticsearch/transport.py", line 358, in perform_request
    timeout=timeout,
  File "/Volumes/Work/Flask_test/Flask_Mega_Tutorial/envf/lib/python3.6/site-packages/elasticsearch/connection/http_urllib3.py", line 261, in perform_request
    self._raise_error(response.status, raw_data)
  File "/Volumes/Work/Flask_test/Flask_Mega_Tutorial/envf/lib/python3.6/site-packages/elasticsearch/connection/base.py", line 182, in _raise_error
    status_code, error_message, additional_info
elasticsearch.exceptions.NotFoundError: NotFoundError(404, 'index_not_found_exception', 'no such index [post]', post, index_or_alias)
2020-02-14 09:46:08,898 INFO: Microblog startup [in /Volumes/Work/Flask_test/Flask_Mega_Tutorial/Flask_mega/app/__init__.py:79]
